Workbook
Name FLUIDCATEGORY: Fields!$E$2:$F$8
Name FLUIDTYPE: Fields!$E$2:$F$8

Sheet Revision, License & Use
B2: Version | C2: Description | D2: Date
B3: 1.0 | C3: Immersion Requirements rev 1 checklist | D3: 43703
B4: 2.0 | C4: Immersion Requirements rev2 checklist | D4: 44552
B5: 2.1 | C5: Immersion Requirements rev2 1st amended checklist | D5: 45156
B6: 2.1 | C6: Fluids-only extract | D6: 45359
C9: Instructions: | D9: Links
B10: Step 1 | C10: Enter all required disclosure values on the Specification tab: | D10: {=MID(CELL("filename",'Specification sheet'!C9),FIND("]",CELL("filename",'Specification sheet'!C9))+1,255)} -> Specification sheet
B11: Step 2 | C11: Verify the generated data on the Specsheet tab: | D11: {=MID(CELL("filename",'GENERATED FLUID SPECSHEET'!B1),FIND("]",CELL("filename",'GENERATED FLUID SPECSHEET'!B1))+1,255)} -> GENERATED FLUID SPECSHEET
B12: Step 3 | C12: Send this specsheet as attachment to (one of the) the Immersion Project Leads: | D12: Rolf.Brink@ocproject.net and John.Bean@ocproject.net
C14: This work is licensed under a Creative Commons Attribution 4.0 International License.
C16: For more information, please check the OCP Immersion wiki: | D16: https://www.opencompute.org/wiki/Cooling_Environments/Immersion

Sheet Specification sheet
B2: Light orange cells require input
B3: Colored cells with bold text have related qualifying values
B4: Green cells indicate qualifying values
B5: Pink cells indicate disqualifying values and require remarks
B6: White cells are optional
B7: Grey cells may not be adjusted
B9: Fluid category | C9: Hydrocarbons | D9: TARGET CUT: Group III narrow cut C21-C25 (n-paraffin equivalent): KV100 ~2.6 cSt (simulated mu25 ~13.6 mPa.s vs <= 15), SimDis T5 >= ~357 C and T95 <= ~402 C (light tail below C21 and heavy end above C25 removed). Thermal, viscosity and resistivity: measured 2 cSt Group III of equivalent viscosity (CRC Report AVFL-37, SwRI 2022). Fire-safety and dielectric values: literature ESTIMATES, marked in Remarks with basis and confidence. Not measurements.
B11: Chapter 4,1, Immersion fluids | D11: Minimum req | E11: Qualification | F11: Remarks (optional)
B12: 2-phase/fluorocarbons specific specifications | D12: =#REF!&#REF! -> #NAME?
B13: Boiling point temperature | C13: ASTM D2887 | D13: 10% of mass has boiled (If below fire point OR decomposition point) | E13: =IF('Specification sheet'!C9=Fields!E6,"*ENTER THIS VALUE FIRST*",IF('Specification sheet'!C9=Fields!E8,Fields!F8,"N/A")) -> N/A
B14: Latent heat of vaporization | C14: ASTM E2071 | D14: 2-phase only | E14: =IF('Specification sheet'!C9=Fields!E6,0,IF('Specification sheet'!C9=Fields!E8,Fields!F8,Fields!$B$9)) -> N/A
B15: Surface tension | C15: ASTM D1331 | D15: 2-phase only | E15: =IF(C9=Fields!E6,0,IF(C9=Fields!E8,Fields!F8,Fields!$B$9)) -> N/A
B16: Vapor density | C16: TBD | D16: 2-phase only | E16: =IF(C9=Fields!E6,0,IF(C9=Fields!E8,Fields!F8,Fields!$B$9)) -> N/A
B17: Dielectric specifications | D17: =#REF!&#REF! -> #NAME?
B18: Dielectric strength, measured at 1 mm | C18: ASTM D 1816 | D18: =D84 -> 6 | E18: 10 | F18: ESTIMATE (low, conservative): entered at the low end of 10-25 kV/mm (as received); dried/filtered new fluid likely 25-40 kV/mm (fresh GTL and mineral transformer oils 78 kV per 2.5 mm, IEC 60156). Measure ASTM D1816
B19: Volume resistivity | C19: ASTM D1169 | D19: =D85 -> 2 | E19: 12400 | F19: CRC AVFL-37 (SwRI 2022), 'Group III B, 2 cSt' Table 9, ASTM D1169 at 25 C, mean of 2 runs (1.24E15 ohm.cm)
B20: Dielectric Constant (Relative permittivity) Measured at: 5 VAC, 20 GHz and 40 GHz, 20°C and 70°C | C20: There is no prescribed method at this point. IEC 60247 may or may not provide a basis for this testing procedure. NB: The high temperature 70°C test can be lowered in line with evaporation temperatures of 2-phase fluids | D20: 20 GHz @ 20°C | E20: 2.14 | F20: ESTIMATE (medium): Dk ~ n^2 for a nonpolar saturated oil; Lorentz-Lorenz with squalane/n-hexadecane specific refraction on the measured density (range 2.08-2.17 at 20 C, 2.02-2.11 at 70 C). Cross-checks: GTL immersion fluid TDS 2.02; synthetic coolant EC-110 2.17 to 2.06 over 5-49 GHz. Measure n_D (ASTM D1218) and Dk
D21: 40 GHz @ 20°C | E21: 2.14
D22: ="20 GHz @ "&IF(C9=Fields!E$6,'Specification sheet'!E$13,70)&"°C" -> 20 GHz @ 70°C | E22: 2.08
D23: ="40 GHz @ "&IF(C9=Fields!E$6,'Specification sheet'!E$13,70)&"°C" -> 40 GHz @ 70°C | E23: 2.08
B24: Loss tangent | C24: Data must be associated with tests conducted for Dielectric Constant with the referenced properties | D24: 20 GHz @ 20°C | E24: 0.001 | F24: ESTIMATE (low, conservative): entered as upper bound 1E-3; likely ~1E-4 to 1E-3 (EC-110: 5.8E-4 at 20.5 GHz, 4.6E-4 at 39.9 GHz). Well inside the 0.05 limit either way
D25: 40 GHz @ 20°C | E25: 0.001
D26: ="20 GHz @ "&IF(C9=Fields!E$6,'Specification sheet'!E$13,70)&"°C" -> 20 GHz @ 70°C | E26: 0.001
D27: ="40 GHz @ "&IF(C9=Fields!E$6,'Specification sheet'!E$13,70)&"°C" -> 40 GHz @ 70°C | E27: 0.001
B28: Maximum moisture content for dielectric breakdown (100% Water saturation point) | C28: ASTM D1533-20 | D28: =Fields!B$19 -> 20 | E28: 53 | F28: ESTIMATE (medium, upper bound): ppm; Oommen relation for mineral insulating oil, log10 ppm = 7.42 - 1670/T(K); a fully saturated paraffinic oil is probably equal or lower
D29: =Fields!B$20 -> 30 | E29: 82
D30: =Fields!B$21 -> 40 | E30: 122
D31: =Fields!B$22 -> 50 | E31: 179
D32: =Fields!B$23 -> 60 | E32: 255
D33: =Fields!B$24 -> 70 | E33: 358
B34: Density | C34: ISO 12185 | D34: =Fields!B$19 -> 20 | E34: 832.2 | F34: kg/m3. CRC AVFL-37 (SwRI 2022), 'Group III B, 2 cSt' Table 6 (40/60/80/95 C), least-squares line
D35: =Fields!B$20 -> 30 | E35: 825.7
D36: =Fields!B$21 -> 40 | E36: 819.2
D37: =Fields!B$22 -> 50 | E37: 812.7
D38: =Fields!B$23 -> 60 | E38: 806.1
D39: =Fields!B$24 -> 70 | E39: 799.6
B40: Specific heat | C40: ASTM E 1269 | D40: =Fields!B$19 -> 20 | E40: 1746 | F40: J/kg.K. CRC AVFL-37 (SwRI 2022), 'Group III B, 2 cSt' Table 8 (0/40/70/100 C), linear interpolation
D41: =Fields!B$20 -> 30 | E41: 1774
D42: =Fields!B$21 -> 40 | E42: 1802
D43: =Fields!B$22 -> 50 | E43: 1833
...

Sheet GENERATED FLUID SPECSHEET
B1: Do not edit this sheet. It is generated and populated from the Specification sheet.
B4: Characteristics | C4: Method | D4: Value
B5: Fluid family | C5: OCP Requirements | D5: ='Specification sheet'!C9 -> Hydrocarbons
B6: ='Specification sheet'!B18 -> Dielectric strength, measured at 1 mm | C6: ='Specification sheet'!C18 -> ASTM D 1816 | D6: ='Specification sheet'!E18 -> 10
B7: ='Specification sheet'!B19 -> Volume resistivity | C7: ='Specification sheet'!C19 -> ASTM D1169 | D7: ='Specification sheet'!E19 -> 12400
B8: ='Specification sheet'!B64 -> Volumetric expansion | C8: ='Specification sheet'!C64 -> ASTM D 1903 | D8: ='Specification sheet'!E64 -> 0.000787
B9: ='Specification sheet'!B65 -> Pour point | C9: ='Specification sheet'!C65 -> ASTM D 97 / ISO 3016 | D9: ='Specification sheet'!E65 -> -42
B10: ='Specification sheet'!B66 -> Flash point (Cleveland Closed Cup) | C10: ='Specification sheet'!C66 -> ASTM D 93 / ISO 2719 | D10: ='Specification sheet'!E66 -> 163
B11: ='Specification sheet'!B67 -> Fire point | C11: ='Specification sheet'!C67 -> ASTM D 92 / 2592 | D11: ='Specification sheet'!E67 -> 195
B12: ='Specification sheet'!B68 -> Auto ignition point | C12: ='Specification sheet'!C68 -> DIN 51794/ ASTM E659 | D12: ='Specification sheet'!E68 -> 260
B13: ='Specification sheet'!B69 -> Sulphur content | C13: ='Specification sheet'!C69 -> ISO 14596 | D13: ='Specification sheet'!E69 -> 1
B14: ='Specification sheet'!B70 -> Acidity | C14: ='Specification sheet'!C70 -> IEC 62021-2 / IEC 62021-1 | D14: ='Specification sheet'!E70 -> 0.02
B15: ='Specification sheet'!B71 -> NFS Nonfood Compounds Certification | C15: ='Specification sheet'!C71 -> NFS certificate | D15: ='Specification sheet'!E71 -> (Select from list)
B16: ='Specification sheet'!B72 -> Odor | D16: ='Specification sheet'!E72 -> Characteristic, faint mineral oil (SDS)
B17: ='Specification sheet'!B73 -> Color | C17: ='Specification sheet'!C73 -> ASTM D 156 / ISO 2211 | D17: ='Specification sheet'!E73 -> L0.5 (ASTM D1500)
B18: ='Specification sheet'!B74 -> Hazard statements, GHS Classification | C18: ='Specification sheet'!C74 -> GHS Classification | D18: ='Specification sheet'!E74 -> Expected Asp. Tox. 1, H304 - confirm on supplier SDS
B19: ='Specification sheet'!B75 -> STOT - single exposure | D19: ='Specification sheet'!E75 -> {SDS spec}
B20: ='Specification sheet'!B76 -> STOT - repeated exposure | D20: ='Specification sheet'!E76 -> {SDS spec}
B21: ='Specification sheet'!B77 -> Biodegradability | C21: ='Specification sheet'!C77 -> OECD 301 | D21: ='Specification sheet'!E77 -> Inherently
B22: ='Specification sheet'!B78 -> Oxidation Stability | C22: ='Specification sheet'!C78 -> IEC 61125 | D22: ='Specification sheet'!E78 -> Not in public data
B23: ='Specification sheet'!B79 -> Global warming potential (GWP) | C23: ='Specification sheet'!C79 -> IPCC 2007 | D23: ='Specification sheet'!E79 -> Negligible (no fluorinated content)
B24: ='Specification sheet'!B80 -> Ozone Depletion Potential | D24: ='Specification sheet'!E80 -> (Select from list)
B26: Fluid physical properties | C26: Max moisture ASTM D1533-20 | D26: Density ISO 12185 | E26: Specific heat ASTM E 1269 | F26: Thermal conductivity ASTM D 7896 | G26: Kinematic viscosity ASTM D7042 | H26: Dynamic viscosity (cp) (calculated) | I26: Dynamic viscosity N-s/m2 (calculated) | J26: Vapour pressure ASTM D2879/ASTM D6378
B27: =IF('Specification sheet'!C$9=Fields!E$6,IF('Specification sheet'!E$13>Fields!B19,Fields!B19,Fields!$B$9),Fields!B19) -> 20 | C27: =IF(Table_Fluidprop_10C[[#This Row],[Fluid physical properties]]=Fields!$B$9,"",'Specification sheet'!E28) -> 53 | D27: =IF(Table_Fluidprop_10C[[#This Row],[Fluid physical properties]]=Fields!$B$9,"",'Specification sheet'!E34) -> 832.2 | E27: =IF(Table_Fluidprop_10C[[#This Row],[Fluid physical properties]]=Fields!$B$9,"",'Specification sheet'!E40) -> 1746 | F27: =IF(Table_Fluidprop_10C[[#This Row],[Fluid physical properties]]=Fields!$B$9,"",'Specification sheet'!E46) -> 0.1288 | G27: =IF(Table_Fluidprop_10C[[#This Row],[Fluid physical properties]]=Fields!$B$9,"",'Specification sheet'!E52) -> 19.14 | H27: =IF(Table_Fluidprop_10C[[#This Row],[Fluid physical properties]]=Fields!$B$9,"",G27*D27/1000) -> 15.928308 | I27: =IF(Table_Fluidprop_10C[[#This Row],[Fluid physical properties]]=Fields!$B$9,"",Table_Fluidprop_10C[[#This Row],[Dynamic viscosity (cp) (calculated)]]/1000) -> 0.015928308 | J27: =IF(Table_Fluidprop_10C[[#This Row],[Fluid physical properties]]=Fields!$B$9,"",'Specification sheet'!E58) -> 2e-06
B28: =IF('Specification sheet'!C$9=Fields!E$6,IF('Specification sheet'!E$13>Fields!B20,Fields!B20,Fields!$B$9),Fields!B20) -> 30 | C28: =IF(Table_Fluidprop_10C[[#This Row],[Fluid physical properties]]=Fields!$B$9,"",'Specification sheet'!E29) -> 82 | D28: =IF(Table_Fluidprop_10C[[#This Row],[Fluid physical properties]]=Fields!$B$9,"",'Specification sheet'!E35) -> 825.7 | E28: =IF(Table_Fluidprop_10C[[#This Row],[Fluid physical properties]]=Fields!$B$9,"",'Specification sheet'!E41) -> 1774 | F28: =IF(Table_Fluidprop_10C[[#This Row],[Fluid physical properties]]=Fields!$B$9,"",'Specification sheet'!E47) -> 0.1276 | G28: =IF(Table_Fluidprop_10C[[#This Row],[Fluid physical properties]]=Fields!$B$9,"",'Specification sheet'!E53) -> 13.1 | H28: =IF(Table_Fluidprop_10C[[#This Row],[Fluid physical properties]]=Fields!$B$9,"",G28*D28/1000) -> 10.81667 | I28: =IF(Table_Fluidprop_10C[[#This Row],[Fluid physical properties]]=Fields!$B$9,"",Table_Fluidprop_10C[[#This Row],[Dynamic viscosity (cp) (calculated)]]/1000) -> 0.01081667 | J28: =IF(Table_Fluidprop_10C[[#This Row],[Fluid physical properties]]=Fields!$B$9,"",'Specification sheet'!E59) -> 6e-06
B29: =IF('Specification sheet'!C$9=Fields!E$6,IF('Specification sheet'!E$13>Fields!B21,Fields!B21,Fields!$B$9),Fields!B21) -> 40 | C29: =IF(Table_Fluidprop_10C[[#This Row],[Fluid physical properties]]=Fields!$B$9,"",'Specification sheet'!E30) -> 122 | D29: =IF(Table_Fluidprop_10C[[#This Row],[Fluid physical properties]]=Fields!$B$9,"",'Specification sheet'!E36) -> 819.2 | E29: =IF(Table_Fluidprop_10C[[#This Row],[Fluid physical properties]]=Fields!$B$9,"",'Specification sheet'!E42) -> 1802 | F29: =IF(Table_Fluidprop_10C[[#This Row],[Fluid physical properties]]=Fields!$B$9,"",'Specification sheet'!E48) -> 0.1264 | G29: =IF(Table_Fluidprop_10C[[#This Row],[Fluid physical properties]]=Fields!$B$9,"",'Specification sheet'!E54) -> 9.43 | H29: =IF(Table_Fluidprop_10C[[#This Row],[Fluid physical properties]]=Fields!$B$9,"",G29*D29/1000) -> 7.725056 | I29: =IF(Table_Fluidprop_10C[[#This Row],[Fluid physical properties]]=Fields!$B$9,"",Table_Fluidprop_10C[[#This Row],[Dynamic viscosity (cp) (calculated)]]/1000) -> 0.007725056 | J29: =IF(Table_Fluidprop_10C[[#This Row],[Fluid physical properties]]=Fields!$B$9,"",'Specification sheet'!E60) -> 2e-05
B30: =IF('Specification sheet'!C$9=Fields!E$6,IF('Specification sheet'!E$13>Fields!B22,Fields!B22,Fields!$B$9),Fields!B22) -> 50 | C30: =IF(Table_Fluidprop_10C[[#This Row],[Fluid physical properties]]=Fields!$B$9,"",'Specification sheet'!E31) -> 179 | D30: =IF(Table_Fluidprop_10C[[#This Row],[Fluid physical properties]]=Fields!$B$9,"",'Specification sheet'!E37) -> 812.7 | E30: =IF(Table_Fluidprop_10C[[#This Row],[Fluid physical properties]]=Fields!$B$9,"",'Specification sheet'!E43) -> 1833 | F30: =IF(Table_Fluidprop_10C[[#This Row],[Fluid physical properties]]=Fields!$B$9,"",'Specification sheet'!E49) -> 0.1252 | G30: =IF(Table_Fluidprop_10C[[#This Row],[Fluid physical properties]]=Fields!$B$9,"",'Specification sheet'!E55) -> 7.08 | H30: =IF(Table_Fluidprop_10C[[#This Row],[Fluid physical properties]]=Fields!$B$9,"",G30*D30/1000) -> 5.753916 | I30: =IF(Table_Fluidprop_10C[[#This Row],[Fluid physical properties]]=Fields!$B$9,"",Table_Fluidprop_10C[[#This Row],[Dynamic viscosity (cp) (calculated)]]/1000) -> 0.005753916 | J30: =IF(Table_Fluidprop_10C[[#This Row],[Fluid physical properties]]=Fields!$B$9,"",'Specification sheet'!E61) -> 5e-05
B31: =IF('Specification sheet'!C$9=Fields!E$6,IF('Specification sheet'!E$13>Fields!B23,Fields!B23,Fields!$B$9),Fields!B23) -> 60 | C31: =IF(Table_Fluidprop_10C[[#This Row],[Fluid physical properties]]=Fields!$B$9,"",'Specification sheet'!E32) -> 255 | D31: =IF(Table_Fluidprop_10C[[#This Row],[Fluid physical properties]]=Fields!$B$9,"",'Specification sheet'!E38) -> 806.1 | E31: =IF(Table_Fluidprop_10C[[#This Row],[Fluid physical properties]]=Fields!$B$9,"",'Specification sheet'!E44) -> 1865 | F31: =IF(Table_Fluidprop_10C[[#This Row],[Fluid physical properties]]=Fields!$B$9,"",'Specification sheet'!E50) -> 0.1241 | G31: =IF(Table_Fluidprop_10C[[#This Row],[Fluid physical properties]]=Fields!$B$9,"",'Specification sheet'!E56) -> 5.5 | H31: =IF(Table_Fluidprop_10C[[#This Row],[Fluid physical properties]]=Fields!$B$9,"",G31*D31/1000) -> 4.43355 | I31: =IF(Table_Fluidprop_10C[[#This Row],[Fluid physical properties]]=Fields!$B$9,"",Table_Fluidprop_10C[[#This Row],[Dynamic viscosity (cp) (calculated)]]/1000) -> 0.00443355 | J31: =IF(Table_Fluidprop_10C[[#This Row],[Fluid physical properties]]=Fields!$B$9,"",'Specification sheet'!E62) -> 0.00015
B32: =IF('Specification sheet'!C$9=Fields!E$6,IF('Specification sheet'!E$13>Fields!B24,Fields!B24,Fields!$B$9),Fields!B24) -> 70 | C32: =IF(Table_Fluidprop_10C[[#This Row],[Fluid physical properties]]=Fields!$B$9,"",'Specification sheet'!E33) -> 358 | D32: =IF(Table_Fluidprop_10C[[#This Row],[Fluid physical properties]]=Fields!$B$9,"",'Specification sheet'!E39) -> 799.6 | E32: =IF(Table_Fluidprop_10C[[#This Row],[Fluid physical properties]]=Fields!$B$9,"",'Specification sheet'!E45) -> 1896 | F32: =IF(Table_Fluidprop_10C[[#This Row],[Fluid physical properties]]=Fields!$B$9,"",'Specification sheet'!E51) -> 0.1229 | G32: =IF(Table_Fluidprop_10C[[#This Row],[Fluid physical properties]]=Fields!$B$9,"",'Specification sheet'!E57) -> 4.39 | H32: =IF(Table_Fluidprop_10C[[#This Row],[Fluid physical properties]]=Fields!$B$9,"",G32*D32/1000) -> 3.510244 | I32: =IF(Table_Fluidprop_10C[[#This Row],[Fluid physical properties]]=Fields!$B$9,"",Table_Fluidprop_10C[[#This Row],[Dynamic viscosity (cp) (calculated)]]/1000) -> 0.003510244 | J32: =IF(Table_Fluidprop_10C[[#This Row],[Fluid physical properties]]=Fields!$B$9,"",'Specification sheet'!E63) -> 0.0004
B34: Dielectric Constant and Loss tangent (@5VAC) | C34: Dielectric Constant | D34: Loss Tangent
B35: ='Specification sheet'!D20 -> 20 GHz @ 20°C | C35: ='Specification sheet'!E20 -> 2.14 | D35: ='Specification sheet'!E24 -> 0.001
B36: ='Specification sheet'!D21 -> 40 GHz @ 20°C | C36: ='Specification sheet'!E21 -> 2.14 | D36: ='Specification sheet'!E25 -> 0.001
B37: ='Specification sheet'!D22 -> 20 GHz @ 70°C | C37: ='Specification sheet'!E22 -> 2.08 | D37: ='Specification sheet'!E26 -> 0.001
B38: ='Specification sheet'!D23 -> 40 GHz @ 70°C | C38: ='Specification sheet'!E23 -> 2.08 | D38: ='Specification sheet'!E27 -> 0.001
B40: Figure of merit | C40: FOM1 | D40: FOM2 | E40: FOM3
B41: =Fields!B19 -> 20 | C41: =F27*(D$8*E27*D27^2/I27/F27)^0.2813 -> 35.299703 | D41: =F27*(D27*E27/F27)^(1/3) -> 28.886919 | E41: =I27 -> 0.015928308
B42: =Fields!B20 -> 30 | C42: =F28*(D$8*E28*D28^2/I28/F28)^0.2813 -> 39.098214 | D42: =F28*(D28*E28/F28)^(1/3) -> 28.784526 | E42: =I28 -> 0.01081667
B43: =Fields!B21 -> 40 | C43: =F29*(D$8*E29*D29^2/I29/F29)^0.2813 -> 42.688765 | D43: =F29*(D29*E29/F29)^(1/3) -> 28.67783 | E43: =I29 -> 0.007725056
B44: =Fields!B22 -> 50 | C44: =F30*(D$8*E30*D30^2/I30/F30)^0.2813 -> 46.074704 | D44: =F30*(D30*E30/F30)^(1/3) -> 28.582516 | E44: =I30 -> 0.005753916
B45: =Fields!B23 -> 60 | C45: =F31*(D$8*E31*D31^2/I31/F31)^0.2813 -> 49.28067 | D45: =F31*(D31*E31/F31)^(1/3) -> 28.501679 | E45: =I31 -> 0.00443355
...

Sheet Fields
B2: Qualifyers | C2: Rack type | D2: Solution Type | E2: Fluid types | F2: Acidity | G2: Source | H2: Chassis type | I2: Max chassis form factor | J2: IT brand compatibility | K2: Feature classification | L2: Biodegradability
B3: Yes | C3: Rack | D3: Single phase | E3: Hydrocarbons | F3: 0.01 | G3: Commodity | H3: Enclosed | I3: 15"U | J3: Proprietary (own) | K3: None | L3: Readily
B4: No | C4: Tank | D4: Dual phase | E4: Natural Esters | F4: 0.06 | G4: Proprietary | H4: Immersion optimized | I4: 19"U | J4: Agnostic | K4: Thermal optimized | L4: Inherently
B5: N/A | C5: Other (elaborate) | D5: Other (elaborate) | E5: Synthetic Esters | F5: 0.03 | G5: =$B$7 -> (Select from list) | H5: Air | I5: 21"U | J5: Specific brand only (elaborate) | K5: Thermal Optimized & High safety | L5: Persistent
B6: Unsure (elaborate) | C6: =$B$7 -> (Select from list) | D6: =$B$7 -> (Select from list) | E6: Fluorocarbons | F6: 0.001 | H6: =$B$7 -> (Select from list) | I6: 15"OU | J6: Other (Elaborate) | K6: Thermal Optimized, High safety, High availability | L6: =$B$7 -> (Select from list)
B7: (Select from list) | E7: Other (elaborate) | F7: NOT LISTED | I7: 19"OU | J7: =$B$7 -> (Select from list)
E8: START HERE: (Select from list) | F8: {SELECT FLUID CATEGORY FIRST (C9)} | I8: 21"OU
B9: N/A | I9: Custom (elaborate)
I10: Other (Elaborate)
I11: =$B$7 -> (Select from list)
B18: Test temperatures | C18: Test temperatures+@ | D18: Rack Capacity
B19: 20 | C19: @ 20°C | D19: RU
B20: 30 | C20: @ 30°C | D20: OU
B21: 40 | C21: @ 40°C | D21: =$B$7 -> (Select from list)
B22: 50 | C22: @ 50°C
B23: 60 | C23: @ 60°C
B24: 70 | C24: @ 70°C
